{
 "cells": [
  {
   "cell_type": "markdown",
   "metadata": {},
   "source": [
    "<h3>Q1. What is an exception in python? Differences between Exceptions and Syntax Errors:</h3>\n",
    "<p><b>Answer.</b></p>\n",
    " <h3>Exception Handling in Python</h3>\n",
    "    \n",
    "<p>\n",
    "        In Python, an <strong>exception</strong> is an abnormal event that occurs during the execution of a program, disrupting the normal flow of the program's instructions. When an exception occurs, the Python interpreter raises the exception, and the program can handle it to prevent the termination of the script.\n",
    "    </p>\n",
    "\n",
    "<h3>Differences between Exceptions and Syntax Errors</h3>\n",
    "\n",
    "<table border=\"1\">\n",
    "        <tr>\n",
    "            <th>Aspect</th>\n",
    "            <th>Exception</th>\n",
    "            <th>Syntax Error</th>\n",
    "        </tr>\n",
    "        <tr>\n",
    "            <td>Occurrence</td>\n",
    "            <td>During runtime</td>\n",
    "            <td>During compilation</td>\n",
    "        </tr>\n",
    "        <tr>\n",
    "            <td>Nature</td>\n",
    "            <td>Result of unexpected conditions</td>\n",
    "            <td>Errors in the syntax of the code</td>\n",
    "        </tr>\n",
    "        <tr>\n",
    "            <td>Examples</td>\n",
    "            <td>Division by zero, accessing an index beyond the length of a list</td>\n",
    "            <td>Missing colons, incorrect indentation, using an invalid variable name</td>\n",
    "        </tr>\n",
    "    </table>\n"
   ]
  },
  {
   "cell_type": "markdown",
   "metadata": {},
   "source": [
    "<h3>Q2. What happenes when an exception is not handled ? Explain with example. </h3>\n",
    "<p><b>Answer.</b></p>\n",
    "\n",
    "<h3>Unhandled Exception Example</h3>\n",
    "    \n",
    "<p>\n",
    "        When an exception is not handled in Python, it leads to the termination of the program's normal execution. The unhandled exception propagates up the call stack until it reaches the top-level of the program, causing the script to terminate. In this scenario, the interpreter prints an error message, including information about the type of exception and the traceback (sequence of function calls leading to the exception).\n",
    "    </p>\n",
    "\n",
    " <h3>Example: Division by Zero Without Exception Handling</h3>\n",
    "\n",
    "<pre>\n",
    "        <code>\n",
    "def divide_numbers(a, b):\n",
    "    result = a / b\n",
    "    return result\n",
    "\n",
    "# Triggering an exception by dividing by zero\n",
    "result = divide_numbers(10, 0)\n",
    "\n",
    "# The following code will not be executed due to the unhandled exception\n",
    "print(\"This line will not be reached.\")\n",
    "        </code>\n",
    "    </pre>\n",
    "\n",
    "   <p>\n",
    "        When the program terminates due to an unhandled exception, Python prints an error message to the console, indicating the type of exception and the traceback. In this case, you might see something like:\n",
    "    </p>\n",
    "\n",
    "<pre>\n",
    "        <code>\n",
    "Traceback (most recent call last):\n",
    "  File \"example.py\", line 8, in &lt;module&gt;\n",
    "    result = divide_numbers(10, 0)\n",
    "  File \"example.py\", line 4, in divide_numbers\n",
    "    result = a / b\n",
    "ZeroDivisionError: division by zero\n",
    "        </code>\n",
    "    </pre>\n",
    "\n",
    "<p>\n",
    "        To avoid such abrupt terminations, it is a good practice to implement exception handling using try-except blocks. This allows the program to gracefully handle exceptions and take appropriate actions, preventing unexpected terminations and providing better control over error scenarios.\n",
    "    </p>"
   ]
  },
  {
   "cell_type": "code",
   "execution_count": null,
   "metadata": {},
   "outputs": [],
   "source": [
    "\"\"\"Q3. Which python statement is used to catch and handle the exception? Explian with an example.\"\"\"\n",
    "\n",
    "\"\"\"Answer\n",
    "        \n",
    "In Python, the try, except, else, and finally statements are used to catch and handle exceptions.\n",
    "These statements are part of the try-except block,\n",
    "which allows you to write code that may raise exceptions and specify how to handle them gracefully.\"\"\"\n",
    "\n",
    "try:\n",
    "    # Code that may raise an exception\n",
    "    num1 = int(input(\"Enter the numerator: \"))\n",
    "    num2 = int(input(\"Enter the denominator: \"))\n",
    "    result = num1 / num2\n",
    "\n",
    "except ValueError:\n",
    "    # Handling a specific exception (ValueError)\n",
    "    print(\"Invalid input. Please enter valid integers.\")\n",
    "\n",
    "except ZeroDivisionError:\n",
    "    # Handling another specific exception (ZeroDivisionError)\n",
    "    print(\"Cannot divide by zero. Please enter a non-zero denominator.\")\n",
    "\n",
    "else:\n",
    "    # Code to execute if no exception occurred\n",
    "    print(\"Result of the division:\", result)\n",
    "\n",
    "finally:\n",
    "    # Cleanup code that runs regardless of exceptions\n",
    "    print(\"End of the program.\")\n"
   ]
  },
  {
   "cell_type": "code",
   "execution_count": null,
   "metadata": {},
   "outputs": [],
   "source": [
    "\"\"\"Q4 explanation with an example involving try, except, else, and finally blocks, along with the raise statement\"\"\"\n",
    "\n",
    "def divide_numbers(num1, num2):\n",
    "    try:\n",
    "        result = num1 / num2\n",
    "    except ZeroDivisionError:\n",
    "        print(\"Error: Cannot divide by zero.\")\n",
    "    else:\n",
    "        print(\"Result of the division:\", result)\n",
    "    finally:\n",
    "        print(\"Division operation completed.\")\n",
    "\n",
    "# Example 1: Valid division\n",
    "divide_numbers(10, 2)\n",
    "\n",
    "# Example 2: Division by zero (will trigger an exception)\n",
    "divide_numbers(5, 0)\n",
    "\n",
    "# Example 3: Using 'raise' to intentionally trigger an exception\n",
    "def validate_input(value):\n",
    "    try:\n",
    "        if not isinstance(value, int):\n",
    "            raise ValueError(\"Input must be an integer.\")\n",
    "        print(\"Input is valid.\")\n",
    "    except ValueError as e:\n",
    "        print(f\"Error: {e}\")\n",
    "    else:\n",
    "        print(\"Processing input.\")\n",
    "    finally:\n",
    "        print(\"Input validation completed.\")\n",
    "\n",
    "# Example 4: Valid input\n",
    "validate_input(15)\n",
    "\n",
    "# Example 5: Invalid input (will trigger a ValueError)\n",
    "validate_input(\"invalid\")\n"
   ]
  },
  {
   "cell_type": "markdown",
   "metadata": {},
   "source": [
    "<h3>Q5. What are custom exception in pyhton? Why do we need custom exception? With examples.</h3>\n",
    "<p><b>Answer.</b></p>\n",
    "<h3>Custom Exceptions Example</h3>\n",
    "    \n",
    "<p>\n",
    "        Custom exceptions, also known as user-defined exceptions, are exceptions that are created by the programmer to handle specific error conditions in their code. Python allows you to define your own exception classes by inheriting from the built-in <code>Exception</code> class or one of its subclasses.\n",
    "    </p>\n",
    "\n",
    "<h3>Why do we need Custom Exceptions?</h3>\n",
    "\n",
    "<ol>\n",
    "        <li>\n",
    "            <strong>Specificity:</strong> Custom exceptions allow developers to create exception classes tailored to their application's specific error conditions. This makes the code more expressive and helps in pinpointing the cause of an issue.\n",
    "        </li>\n",
    "        <li>\n",
    "            <strong>Clarity and Readability:</strong> Using custom exceptions enhances code readability by providing clear names for error conditions, making it easier for other developers to understand the code.\n",
    "        </li>\n",
    "        <li>\n",
    "            <strong>Modularity:</strong> Custom exceptions promote modularity by encapsulating error-handling logic within the exception class. This makes the code more maintainable and promotes a clean separation of concerns.\n",
    "        </li>\n",
    "    </ol>\n",
    "\n",
    "<h3>Example:</h3>\n",
    "\n",
    "<pre>\n",
    "        <code>\n",
    "class InsufficientFundsError(Exception):\n",
    "    def __init__(self, balance, amount):\n",
    "        self.balance = balance\n",
    "        self.amount = amount\n",
    "        super().__init__(f\"Insufficient funds. Current balance: {balance}, Withdrawal amount: {amount}\")\n",
    "\n",
    "class BankAccount:\n",
    "    def __init__(self, balance):\n",
    "        self.balance = balance\n",
    "\n",
    "    def withdraw(self, amount):\n",
    "        if amount > self.balance:\n",
    "            raise InsufficientFundsError(self.balance, amount)\n",
    "        else:\n",
    "            self.balance -= amount\n",
    "            print(f\"Withdrawal successful. Remaining balance: {self.balance}\")\n",
    "\n",
    "# Example usage\n",
    "account = BankAccount(1000)\n",
    "\n",
    "try:\n",
    "    account.withdraw(1500)\n",
    "except InsufficientFundsError as e:\n",
    "    print(f\"Error: {e}\")\n",
    "        </code>\n",
    "    </pre>\n",
    "\n",
    "<p>\n",
    "        In this example, <code>InsufficientFundsError</code> is a custom exception class that inherits from the built-in <code>Exception</code> class. The <code>BankAccount</code> class uses this custom exception to raise an error when a withdrawal amount exceeds the account balance. When an <code>InsufficientFundsError</code> is caught, it provides detailed information about the balance and the attempted withdrawal amount.\n",
    "    </p>\n",
    "\n",
    "<p>\n",
    "        Using custom exceptions in this way allows for clear and specific error handling in the application, making the code more robust and maintainable.\n",
    "    </p>\n"
   ]
  },
  {
   "cell_type": "code",
   "execution_count": null,
   "metadata": {},
   "outputs": [],
   "source": [
    "\"\"\"Q6. Create custom exception class. Use this class to handle exception.\"\"\"\n",
    "\n",
    "class CustomError(Exception):\n",
    "    def __init__(self, message):\n",
    "        super().__init__(message)\n",
    "\n",
    "def example_function(value):\n",
    "    try:\n",
    "        if value < 0:\n",
    "            raise CustomError(\"Negative values are not allowed.\")\n",
    "        else:\n",
    "            print(\"Value is:\", value)\n",
    "    except CustomError as e:\n",
    "        print(f\"Custom Error: {e}\")\n",
    "\n",
    "# Example usage\n",
    "try:\n",
    "    example_function(5)\n",
    "    example_function(-3)\n",
    "except CustomError as e:\n",
    "    print(f\"Custom Error outside the function: {e}\")\n"
   ]
  }
 ],
 "metadata": {
  "kernelspec": {
   "display_name": "Python 3",
   "language": "python",
   "name": "python3"
  },
  "language_info": {
   "codemirror_mode": {
    "name": "ipython",
    "version": 3
   },
   "file_extension": ".py",
   "mimetype": "text/x-python",
   "name": "python",
   "nbconvert_exporter": "python",
   "pygments_lexer": "ipython3",
   "version": "3.11.8"
  }
 },
 "nbformat": 4,
 "nbformat_minor": 2
}
